<robot name="bogson">

<link name="base">
  <visual>
    <origin xyz="0 0.0 0.5" rpy="0 0 0"/>
    <geometry>
      <box size="0.5 0.5 1.0" />
    </geometry>
    <material name="0.48505499092652593">
      <color rgba="0.8386912536755906 0.7686551181015421 0.40673635570412814 0.5" />
    </material>
  </visual>
</link>

<link name="pierwszy">
  <visual>
    <origin xyz="0 0.0 1.0" rpy="0 0 0"/>
    <geometry>
      <box size="0.5 0.5 2.0" />
    </geometry>
    <material name="0.6438101007111079">
      <color rgba="0.6397857766405962 0.3466725072913863 0.2576450270627594 0.5" />
    </material>
  </visual>
</link>

<joint name="base_to_pierwszy" type="fixed">
  <origin xyz="0 0.0 1.0" rpy="0.0 0 0.0"/>
  <parent link="base"/>
  <child link="pierwszy"/>
</joint>

<link name="drugi">
  <visual>
    <origin xyz="0 0.0 1.0" rpy="0 0 0"/>
    <geometry>
      <box size="0.5 0.5 2.0" />
    </geometry>
    <material name="0.7943083859635198">
      <color rgba="0.5529530992847452 0.5080797818554239 0.19240496907530535 0.5" />
    </material>
  </visual>
</link>

<joint name="pierwszy_to_drugi" type="revolute">
  <origin xyz="0 0.0 2.0" rpy="0 0 0.0"/>
  <parent link="pierwszy"/>
  <child link="drugi"/>
  <axis xyz="0 1 0" />
  <limit upper="1.57075" lower="-1.57075" effort="10" velocity="10" />
</joint>

<link name="trzeci">
  <visual>
    <origin xyz="0 0.0 1.0" rpy="0 0 0"/>
    <geometry>
      <box size="0.5 0.5 2.0" />
    </geometry>
    <material name="0.7474188918911576">
      <color rgba="0.3374349259317768 0.47865313719670133 0.31330418525617243 0.5" />
    </material>
  </visual>
</link>

<joint name="drugi_to_trzeci" type="revolute">
  <origin xyz="0 0.0 2.0" rpy="0 0 1.5708"/>
  <parent link="drugi"/>
  <child link="trzeci"/>
  <axis xyz="0 1 0" />
  <limit upper="1.57075" lower="-1.57075" effort="10" velocity="10" />
</joint>

<link name="narzedzie">
  <visual>
    <origin xyz="0 0.0 0.5" rpy="0 0 0"/>
    <geometry>
      <box size="0.5 0.5 1.0" />
    </geometry>
    <material name="0.5534070748757144">
      <color rgba="0.9479057043109085 0.43610209131087774 0.980665014240638 0.5" />
    </material>
  </visual>
</link>

<joint name="trzeci_to_narzedzie" type="fixed">
  <origin xyz="0 0.0 2.0" rpy="0.0 0 0.0"/>
  <parent link="trzeci"/>
  <child link="narzedzie"/>
</joint>

</robot>
