<robot name="bogson">

<link name="base">
  <visual>
    <origin xyz="0 0.0 0.5" rpy="0 0 0"/>
    <geometry>
      <box size="0.5 0.5 1.0" />
    </geometry>
    <material name="0.3465439533826242">
      <color rgba="0.41328103599728483 0.7778155754853163 0.23150030637901065 0.5" />
    </material>
  </visual>
</link>

<link name="pierwszy">
  <visual>
    <origin xyz="0 0.0 1.0" rpy="0 0 0"/>
    <geometry>
      <box size="0.5 0.5 2.0" />
    </geometry>
    <material name="0.1265825941282357">
      <color rgba="0.42644811498183355 0.3518196428635404 0.0390478442084885 0.5" />
    </material>
  </visual>
</link>

<joint name="base_to_pierwszy" type="prismatic">
  <origin xyz="0 0.0 1.0" rpy="0.0 0 0.0"/>
  <parent link="base"/>
  <child link="pierwszy"/>
  <axis xyz="0 0 1" />
  <limit upper="4.0" lower="2.0" effort="10" velocity="10" />
</joint>

<link name="drugi">
  <visual>
    <origin xyz="0 0.0 1.0" rpy="0 0 0"/>
    <geometry>
      <box size="0.5 0.5 2.0" />
    </geometry>
    <material name="0.2307139704702924">
      <color rgba="0.47381061153487647 0.35947625197102506 0.24221932163993654 0.5" />
    </material>
  </visual>
</link>

<joint name="pierwszy_to_drugi" type="revolute">
  <origin xyz="0 0.0 2.0" rpy="0 0 0.0"/>
  <parent link="pierwszy"/>
  <child link="drugi"/>
  <axis xyz="0 1 0" />
  <limit upper="1.57075" lower="-1.57075" effort="10" velocity="10" />
</joint>

<link name="trzeci">
  <visual>
    <origin xyz="0 0.0 1.0" rpy="0 0 0"/>
    <geometry>
      <box size="0.5 0.5 2.0" />
    </geometry>
    <material name="0.6373315875351944">
      <color rgba="0.6006314098617382 0.7313820558649545 0.7505314782461727 0.5" />
    </material>
  </visual>
</link>

<joint name="drugi_to_trzeci" type="revolute">
  <origin xyz="0 0.0 2.0" rpy="0 0 1.5708"/>
  <parent link="drugi"/>
  <child link="trzeci"/>
  <axis xyz="0 1 0" />
  <limit upper="1.57075" lower="-1.57075" effort="10" velocity="10" />
</joint>

<link name="narzedzie">
  <visual>
    <origin xyz="0 0.0 0.5" rpy="0 0 0"/>
    <geometry>
      <box size="0.5 0.5 1.0" />
    </geometry>
    <material name="0.6941032887285742">
      <color rgba="0.32213894261466813 0.470072494696505 0.002542699702619222 0.5" />
    </material>
  </visual>
</link>

<joint name="trzeci_to_narzedzie" type="fixed">
  <origin xyz="0 0.0 2.0" rpy="0.0 0 0.0"/>
  <parent link="trzeci"/>
  <child link="narzedzie"/>
</joint>

</robot>
