<robot name="bogson">

<link name="odom"/>

<joint name="odom_to_base" type="prismatic">
  <origin xyz="0 0.0 1.0" rpy="0.0 0 0.0"/>
  <parent link="odom"/>
  <child link="base"/>
  <axis xyz="0 0 1" />
  <limit upper="4.0" lower="2.0" effort="10" velocity="10" />
</joint>

<link name="base">
  <visual>
    <origin xyz="0 0.0 0.5" rpy="0 0 0"/>
    <geometry>
      <box size="0.5 0.5 1.0" />
    </geometry>
    <material name="0.9750062879637011">
      <color rgba="0.793149436554676 0.4294658309110486 0.42143478449268645 0.5" />
    </material>
  </visual>
</link>

<link name="pierwszy">
  <visual>
    <origin xyz="0 0.0 1.0" rpy="0 0 0"/>
    <geometry>
      <box size="0.5 0.5 2.0" />
    </geometry>
    <material name="0.30626266683983305">
      <color rgba="0.3673461596106745 0.03822902997029942 0.8661961213947633 0.5" />
    </material>
  </visual>
</link>

<joint name="base_to_pierwszy" type="prismatic">
  <origin xyz="0 0.0 1.0" rpy="0.0 0 0.0"/>
  <parent link="base"/>
  <child link="pierwszy"/>
  <axis xyz="0 0 1" />
  <limit upper="4.0" lower="2.0" effort="10" velocity="10" />
</joint>

<link name="drugi">
  <visual>
    <origin xyz="0 0.0 1.0" rpy="0 0 0"/>
    <geometry>
      <box size="0.5 0.5 2.0" />
    </geometry>
    <material name="0.09324541759923499">
      <color rgba="0.9538904853911977 0.014999899564075214 0.5117288186871944 0.5" />
    </material>
  </visual>
</link>

<joint name="pierwszy_to_drugi" type="revolute">
  <origin xyz="0 0.0 2.0" rpy="0 0 0.0"/>
  <parent link="pierwszy"/>
  <child link="drugi"/>
  <axis xyz="0 1 0" />
  <limit upper="1.57075" lower="-1.57075" effort="10" velocity="10" />
</joint>

<link name="trzeci">
  <visual>
    <origin xyz="0 0.0 1.0" rpy="0 0 0"/>
    <geometry>
      <box size="0.5 0.5 2.0" />
    </geometry>
    <material name="0.6093032528712037">
      <color rgba="0.6576303715710319 0.7432605643139607 0.38358285266711445 0.5" />
    </material>
  </visual>
</link>

<joint name="drugi_to_trzeci" type="revolute">
  <origin xyz="0 0.0 2.0" rpy="0 0 1.5708"/>
  <parent link="drugi"/>
  <child link="trzeci"/>
  <axis xyz="0 1 0" />
  <limit upper="1.57075" lower="-1.57075" effort="10" velocity="10" />
</joint>

<link name="narzedzie">
  <visual>
    <origin xyz="0 0.0 0.5" rpy="0 0 0"/>
    <geometry>
      <box size="0.5 0.5 1.0" />
    </geometry>
    <material name="0.5044876166279739">
      <color rgba="0.3616587993596653 0.9488624551944466 0.8545729589039096 0.5" />
    </material>
  </visual>
</link>

<joint name="trzeci_to_narzedzie" type="fixed">
  <origin xyz="0 0.0 2.0" rpy="0.0 0 0.0"/>
  <parent link="trzeci"/>
  <child link="narzedzie"/>
</joint>

</robot>
