<?xml version="1.0"?>

<robot name="bogson" xmlns:xacro="http://www.ros.org/wiki/xacro">

    <xacro:property name="DH" value="${load_yaml('DH.yaml')}"/>

    <link name="base">
        <visual>
            <geometry>
                <box size="5 5 0.5"/>
            </geometry>
            <origin rpy="0 0 0" xyz="0 0 ${0.25}"/>
            <material name="magenta">
                <color rgba="1 0 1 0.5"/>
            </material>
        </visual>
    </link>

    <link name="link1">
        <visual>
            <geometry>
                <box size="${DH['link1']['a']} 1 1"/>
            </geometry>
            <origin rpy="0 0 0" xyz="${0.5*DH['link1']['a']} 0 0"/>
            <material name="magenta">
                <color rgba="1 0 1 0.5"/>
            </material>
        </visual>
    </link>

    <joint name="base_to_link1" type="revolute">
        <axis xyz="0 0 1"/>
        <limit upper="1.57075" lower="-1.57075" effort="10" velocity="2" />
        <parent link="base"/>
        <child link="link1"/>
        <origin xyz="0 0 1" rpy="${(DH['link1']['alpha']*pi)/3.14 } 0 ${(DH['link1']['theta']*pi)/3.14 }"/>
    </joint>

    <link name="link2">
        <visual>
            <geometry>
                <box size="${DH['link2']['a']} 1 1"/>
            </geometry>
            <origin rpy="0 0 0" xyz="${0.5*DH['link2']['a']} 0 0"/>
            <material name="magenta">
                <color rgba="1 0 1 0.5"/>
            </material>
        </visual>
    </link>

    <joint name="link1_to_link2" type="revolute">
        <axis xyz="0 0 1"/>
        <limit upper="1.57075" lower="-1.57075" effort="10" velocity="2" />
        <parent link="link1"/>
        <child link="link2"/>
        <origin xyz="${DH['link1']['a']} ${DH['link1']['d']*sin(DH['link1']['alpha'])*(-1)} ${DH['link1']['d']*cos(DH['link1']['alpha'])}" rpy="${(DH['link2']['alpha']*pi)/3.14 } 0 ${(DH['link2']['theta']*pi)/3.14 }"/>
    </joint>

    <link name="link3">
        <visual>
            <geometry>
                    <box size="${DH['link3']['a']} 1 1"/>
                </geometry>
                <origin rpy="0 0 0" xyz="${0.5*DH['link3']['a']} 0 0"/>
            <material name="magenta">
                <color rgba="1 0 1 0.5"/>
            </material>
        </visual>
    </link>

    <joint name="link2_to_link3" type="revolute">
        <axis xyz="0 0 1"/>
        <limit upper="1.57075" lower="-1.57075" effort="10" velocity="2" />
        <parent link="link2"/>
        <child link="link3"/>
        <origin xyz="${DH['link2']['a']} ${DH['link2']['d']*sin(DH['link2']['alpha'])*(-1)} ${DH['link2']['d']*cos(DH['link2']['alpha'])}" rpy="${(DH['link3']['alpha']*pi)/3.14 } 0 ${(DH['link3']['theta']*pi)/3.14 }"/>
    </joint>

    <link name="narzedzie">
        <visual>
            <geometry>
                    <sphere radius="0.5"/>
                </geometry>
                <origin rpy="0 0 0" xyz="0.5 0 0"/>
            <material name="magenta">
                <color rgba="1 0 1 0.5"/>
            </material>
        </visual>
    </link>

    <joint name="link3_to_narzedzie" type="fixed">
        <parent link="link3"/>
        <child link="narzedzie"/>
        <origin xyz="${DH['link3']['a']} ${DH['link3']['d']*sin(DH['link3']['alpha'])*(-1)} ${DH['link3']['d']*cos(DH['link3']['alpha'])}" rpy="0 0 0"/>
    </joint>
</robot>